Workbook
Name _Toc322014478: 'Пр 23 Справочник статей и КУУ'!#REF!
Name _Toc520384594: 'Пр 1 Планы '!$C$1
Name _Toc520384594: 'Пр 24 (иск. из экспл.)'!#REF!
Name _выбор_из_выпадающего_списка: #REF!
Name _выбор_из_выпадающего_списка: 'Пр 3.3 заявка Пл. 104.1-201.1'!$R$12
Name _выбор_из_выпадающего_списка: #REF!
Name _выбор_из_выпадающего_списка: #REF!
Name _выбор_из_выпадающего_списка: #REF!
Name _выбор_из_выпадающего_списка: #REF!
Name _выбор_из_выпадающего_списка: #REF!
Name _табл2: #NAME?
Name A48_табл2: #NAME?
Name aaaaa: #REF!
Name aaaaa: #REF!
Name aaaaa: #REF!
Name aaaaa: #REF!
Name aaaaa: #REF!
Name aaaaa: #REF!
Name aaaaa: #REF!
Name aq: #REF!
Name aq: #REF!
Name aq: #REF!
Name aq: #REF!
Name aq: #REF!
Name aq: #REF!
Name aq: #REF!
Name as: #REF!
Name as: #REF!
Name as: #REF!
Name as: #REF!
Name as: #REF!
Name as: #REF!
Name as: #REF!
Name asweer: #REF!
Name asweer: #REF!
Name asweer: #REF!
Name asweer: #REF!
Name asweer: #REF!
Name asweer: #REF!
Name asweer: #REF!
Name B2К: #REF!
Name B2К: #REF!
Name B2К: #REF!
Name B2К: #REF!
Name B2К: #REF!
Name B2К: #REF!
Name B2К: #REF!
Name B3К: #REF!
Name B3К: #REF!
Name B3К: #REF!
Name B3К: #REF!
Name B3К: #REF!
Name B3К: #REF!
Name B3К: #REF!
Name Button_1: "ГлобалВылеты_Лист1_Таблица"
Name Button_2: "ГлобалВылеты_Лист1_Таблица"
Name cghuyuibjh: #REF!
Name cghuyuibjh: #REF!
Name cghuyuibjh: #REF!
Name cghuyuibjh: #REF!

Sheet Пр 1 Планы 
C1: ПРИЛОЖЕНИЕ № 1
C2: К ПОРЯДКУ ТЕКУЩЕГО ЭКОНОМИЧЕСКОГО ПЛАНИРОВАНИЯ ПРОИЗВОДСТВЕННО-ХОЗЯЙСТВЕННОЙ ДЕЯТЕЛЬНОСТИ ФГУП «ГОСКОРПОРАЦИЯ ПО ОрВД»
A4: Перечень централизованных (ц) и децентрализованных (д) планов ФГУП «Госкорпорация по ОрВД» 1, 2,3 и 4 групп
A5: Группа планов | B5: № подгруппы планов | C5: Наименование плана | D5: Признак ц/д
A6: 1. Централизованные планы мероприятий по модернизации объектов ЕС ОрВД, реализуемых в рамках федеральных целевых программ и по отдельным постановлениям Правительства Российской Федерации
B7: 101.1 | C7: Государственная программа Российской Федерации "Космическая деятельность России» | D7: ц
B8: 104.1 | C8: Централизованный план мероприятий по реализации федерального проекта «Развитие инфраструктуры, обеспечение безопасности и формирование специализированной системы сертификации беспилотных авиационных систем» ФГУП «Госкорпорация по ОрВД» | D8: ц
B9: 105.1 | C9: Централизованный план по развитию опорной сети аэродромов объектов ЕС ОрВД ФГУП "Госкорпорация по ОрВД" | D9: ц
A10: 2. Планы развития и поддержания имущественного комплекса ФГУП «Госкорпорация по ОрВД» (непрограммная часть)
B11: 201.1 | C11: Централизованный план строительства, оснащения и модернизации объектов ЕС ОрВД | D11: ц
B12: 201.2 | C12: План развития и поддержания работоспособности объектов ЕС ОрВД филиала ______ФГУП «Госкорпорация по ОрВД» (часть 1) | D12: д
B13: 202.1 | C13: Централизованный план мероприятий по обеспечению информационной безопасности ФГУП «Госкорпорация по ОрВД» | D13: ц
B14: 202.3 | C14: План мероприятий по обеспечению транспортной безопасности в компетенции филиала_______ФГУП «Госкорпорация по ОрВД» | D14: д
B15: 203.1 | C15: Централизованный план мероприятий по поддержанию и развитию информационных технологий ФГУП «Госкорпорация по ОрВД» | D15: ц
B16: 203.2 | C16: План мероприятий по поддержанию и развитию информационных технологий в компетенции филиала_______ФГУП «Госкорпорация по ОрВД» | D16: д
B17: 205.1 | C17: Централизованный план ремонтно-восстановительных работ ФГУП «Госкорпорация по ОрВД» | D17: ц
B18: 205.2 | C18: План ремонтно-восстановительных работ в компетенции филиала______ФГУП «Госкорпорация по ОрВД» | D18: д
B19: 206.1 | C19: План научно-исследовательских и опытно-конструкторских работ ФГУП «Госкорпорация по ОрВД» | D19: ц
B20: 207.2 | C20: План развития и поддержания работоспособности объектов ЕС ОрВД филиала ______ФГУП «Госкорпорация по ОрВД» (часть 2) | D20: д
B21: 208.2 | C21: План мероприятий по обеспечению информационной безопасности в компетенции филиала_______ФГУП «Госкорпорация по ОрВД» | D21: д
A22: 3. Планы мероприятий для обеспечения производственно-хозяйственной деятельности ФГУП «Госкорпорация по ОрВД»
B23: 301.1 | C23: Централизованный план мероприятий по поисково-спасательному обеспечению в части дежурства поисково-спасательных воздушных судов и экипажей и выполнение дежурными экипажами тренировочных полетов ФГУП «Госкорпорация по ОрВД» | D23: ц
B24: 302.1
A25: 4. Планы мероприятий, инициированные ФГУП «Госкорпорация по ОрВД» в целях повышения квалификации, клиентоориентированности, мотивации персонала, представления Предприятия на международных и российских выставках, форумах и т.д.
B26: 401.1 | C26: Централизованный план профессиональной подготовки и переподготовки ФГУП «Госкорпорация по ОрВД» | D26: ц
B27: 402.1 | C27: Централизованный план мероприятий социальной программы ФГУП «Госкорпорация по ОрВД» | D27: ц
B28: 403.1 | C28: Централизованный план международных и корпоративных мероприятий ФГУП «Госкорпорация по ОрВД» | D28: ц

Sheet Пр 2а Структура планов  
K1: ПРИЛОЖЕНИЕ № 2 а
K2: К ПОРЯДКУ ТЕКУЩЕГО ПЛАНИРОВАНИЯ ПРОИЗВОДСТВЕННО-ХОЗЯЙСТВЕННОЙ ДЕЯТЕЛЬНОСТИ ФГУП «ГОСКОРПОРАЦИЯ ПО ОрВД»
D3: Структура планов ФГУП "Госкорпорация по ОрВД" 1 и 2 группы
A5: № пп | B5: Разделы, подразделы плана | C5: Объекты, средства, системы | D5: Централизованные планы, в том числе по группам | L5: Децентрализованные планы | M5: Наименование подразделений, ответственных за разделы, подразделы плана
D6: планы 1 группы | G6: планы 2 группы
D7: № 101.1. Государственная программа Российской Федерации "Космическая деятельность России» | E7: № 104.1. Централизованный план мероприятий по реализации федерального проекта «Развитие инфраструктуры, обеспечение безопасности и формирование специализированной системы сертификации беспилотных авиационных систем» ФГУП «Госкорпорация по ОрВД» на 20____ год | F7: № 105.1. Централизованный план по развитию опорной сети аэродромов объектов ЕС ОрВД ФГУП "Госкорпорация по ОрВД" на 20____ год | G7: № 201.1. Централизованный план строительства, оснащения и модернизации объектов ЕС ОрВД» на 20____год | H7: № 202.1. Централизованный план мероприятий по обеспечению информационной безопасности ФГУП «Госкорпорация по ОрВД» на 20____год | I7: № 203.1. Централизованный план мероприятий по развитию поддержанию информационных технологий ФГУП «Госкорпорация по ОрВД» на 20____ год | J7: № 205.1. Централизованный план ремонтно-восстановительных работ (РВР) ФГУП «Госкорпорация по ОрВД» на 20____ год | K7: № 206.1. План НИОКР ФГУП «Госкорпорация по ОрВД» на 20____ год | L7: Программа деятельности филиала ФГУП «Госкорпорация по ОрВД» на 20____ год
D9: капитальные | E9: капитальные | F9: капитальные | G9: капитальные | H9: текущие, капитальные | I9: текущие, капитальные | J9: текущие | K9: текущие | L9: текущие, капитальные
D10: 2070311 | E10: 2070314 | F10: 2070315 | G10: 2070322 | H10: 204321/2070323 | I10: 204951/2070324 | J10: 204961 | K10: 20430
A11: 1 | B11: 2 | C11: 3 | D11: 4 | E11: 7 | F11: 8 | G11: 9 | H11: 10 | I11: 11 | J11: 12 | K11: 13 | L11: 14 | M11: 15
A12: 01.0000 | B12: Организация воздушного движения (ОрВД)
A13: 01.0100 | B13: Мероприятия в отношении укрупненных центров, систем и средств ОрВД
A14: 01.0110 | B14: Мероприятия в отношении укрупненных центров ЕС ОрВД
A15: 01.0111 | B15: Мероприятия в отношении укрупненных центров ЕС ОрВД | C15: Укрупненные центры ЕС ОрВД (Cтроительство/реконструкция зданий, модернизация / замена АС ОрВД) | D15: Х | E15: Х | F15: Создание/Проектирование/Приобретение/Поставка/МиПНР/ПСИ/Оснащение/Модернизация/Реконструкция - основные этапы | G15: Создание/Проектирование/Приобретение/Поставка/МиПНР/ПСИ/Оснащение/Модернизация/Реконструкция - основные этапы | H15: Х | I15: Х | J15: Ремонтно-восстановительные работы, поддержание эксплуатационной готовности, выполнение работ по бюллетеням, закупка ЗИП, сервисное сопровождение | K15: Исследования, связанные с созданием, внедрением, применением (эксплуатацией) и модернизацией объектов, средств, систем | L15: Создание/Приобретение/Модернизация/Реконструкция - вспомогательные этапы стоимостью менее 10 млн руб. (ВПО 20701) | M15: Дирекция стратегического развития, эксплуатации и технической политики ГД Филиал
A16: 01.0120 | B16: Мероприятия в отношении комплексов средств автоматизации планирования и использования воздушного пространства
A17: 01.0121 | B17: Мероприятия в отношении комплексов средств автоматизации планирования использования воздушного пространства | C17: Комплексы средств автоматизации планирования использования воздушного пространства (КСА ПИВП ГЦ ЕС ОрВД, зональных, региональных и районных центров ЕС ОрВД, органов ОВД, таких как ГО ПВД, МДП, ВМДП, КДП, КДП МВЛ, КДП МВЛ РЗО, ЦПИ) - (АС ПИВП, КСА ПИВП ЗЦ/УЦ, КСА ПИВП РЦ, КСА ПВД, КСА ПИВП, КСА ПИВП ГО ПВД, КСА ПИВП МДП) | D17: Х | E17: Создание/Проектирование/Приобретение/Поставка/МиПНР/ПСИ/Оснащение/Модернизация/Реконструкция - основные этапы | F17: Создание/Проектирование/Приобретение/Поставка/МиПНР/ПСИ/Оснащение/Модернизация/Реконструкция - основные этапы | G17: Создание/Проектирование/Приобретение/Поставка/МиПНР/ПСИ/Оснащение/Модернизация/Реконструкция - основные этапы | H17: Х | I17: Х | J17: Ремонтно-восстановительные работы, поддержание эксплуатационной готовности, выполнение работ по бюллетеням, закупка ЗИП, сервисное сопровождение | K17: Исследования, связанные с созданием, внедрением, применением (эксплуатацией) и модернизацией объектов, средств, систем | L17: Создание/Приобретение/Модернизация/Реконструкция - вспомогательные этапы (ВПО 20701) | M17: Дирекция стратегического развития, эксплуатации и технической политики ГД Филиал
A18: 01.0130 | B18: Мероприятия в отношении средств и систем ОВД в районах аэродромов
A19: 01.0131 | B19: Мероприятия в отношении средств и систем ОВД в районах аэродромов | C19: Средства и системы ОВД в районах аэродромов (включая строительство КДП и оборудование для КДП, в том числе КТС УВД, КСА НКАД, системы видеонаблюдения для УВД (КСА УВН, АРМ УВД, АС УВД, РАС УВД, КСА УВД, НКАД, АО РЛИ) | D19: Х | E19: Х | F19: Создание (включая строительство КДП)/Приобретение/Поставка/МиПНР/ПСИ/Оснащение/Модернизация/Реконструкция - основные этапы | G19: Создание (включая строительство КДП)/Приобретение/Поставка/МиПНР/ПСИ/Оснащение/Модернизация/Реконструкция - основные этапы | H19: Х | I19: Х | J19: Ремонтно-восстановительные работы, поддержание эксплуатационной готовности, выполнение работ по бюллетеням, закупка ЗИП, сервисное сопровождение | K19: Исследования, связанные с созданием, внедрением, применением (эксплуатацией) и модернизацией объектов, средств, систем | L19: Создание/Приобретение/Модернизация/Реконструкция - вспомогательные этапы стоимостью менее 10 млн руб. (ВПО 20701) | M19: Дирекция стратегического развития, эксплуатации и технической политики ГД Филиал
A20: 01.0140 | B20: Мероприятия в отношении тренажерного оборудования для УЦ
A21: 01.0141 | B21: Мероприятия в отношении тренажерного оборудования для УЦ | C21: Тренажерное оборудование, оборудование учебных классов УЦ (АУК, КДТ) | D21: Х | E21: Х | F21: Х | G21: Создание/Проектирование/Приобретение/Поставка/МиПНР/Оснащение/Модернизация/Реконструкция - основные этапы | H21: Х | I21: Х | J21: Ремонтно-восстановительные работы, поддержание эксплуатационной готовности, выполнение работ по бюллетеням, закупка ЗИП, сервисное сопровождение | K21: Исследования, связанные с созданием, внедрением, применением (эксплуатацией) и модернизацией объектов, средств, систем | L21: Создание/Приобретение/Модернизация/Реконструкция - вспомогательные этапы (ВПО 20701) | M21: Дирекция стратегического развития, эксплуатации и технической политики ГД Филиал
A22: 01.0150 | B22: Мероприятия в отношении средств предоставления АНИ
A23: 01.0151 | B23: Мероприятия в отношении ПАК АНИ | C23: ПАК АНИ | D23: Х | E23: Х | F23: Х | G23: Создание/Проектирование/Приобретение/Поставка/МиПНР/Оснащение/Модернизация/Реконструкция - основные этапы | H23: Х | I23: Х | J23: Х | K23: Исследования, связанные с созданием, внедрением, применением (эксплуатацией) и модернизацией объектов, средств, систем | L23: Создание/Приобретение/Модернизация/Реконструкция - вспомогательные этапы (ВПО 20701)/Ремонтно-восстановительные работы (ВПО 204962) | M23: Дирекция стратегического развития, эксплуатации и технической политики ГД Филиал
A24: 01.0152 | B24: Мероприятия в отношении КАС СИДИМ | C24: КАС СИДИМ | D24: Х | E24: Х | F24: Х | G24: Создание/Проектирование/Приобретение/Поставка/МиПНР/Оснащение/Модернизация/Реконструкция - основные этапы | H24: Х | I24: Х | J24: Ремонтно-восстановительные работы, поддержание эксплуатационной готовности, выполнение работ по бюллетеням, закупка ЗИП, сервисное сопровождение | K24: Исследования, связанные с созданием, внедрением, применением (эксплуатацией) и модернизацией объектов, средств, систем | L24: Создание/Приобретение/Модернизация/Реконструкция - вспомогательные этапы (ВПО 20701)/Ремонтно-восстановительные работы (ВПО 204962) | M24: Дирекция стратегического развития, эксплуатации и технической политики ГД Филиал
A25: 01.0200 | B25: Технологические мероприятия, процессы ОрВД и ИВП
A26: 01.0210 | B26: Технологические мероприятия, процессы ОрВД и ИВП | C26: КИМ ОрВД | D26: Х | E26: Х | F26: Х | G26: Х | H26: Х | I26: Х | J26: Х | K26: Исследования, связанные с технологиями и процессами ОрВД и ИВП | L26: Х | M26: Дирекция стратегического развития, эксплуатации и технической политики ГД
A27: 01.0300 | B27: Мероприятия в отношении прочих средств организации воздушного движения
A28: 01.0310 | B28: Мероприятия в отношении прочих средств организации воздушного движения | C28: Метео, СЕВ, ПД, КПУ, АДИ, АПОИ, КСПИ, СТВ, ИСС | D28: Х | E28: Х | F28: Х | G28: Х | H28: Х | I28: Х | J28: Х | K28: Х | L28: Приобретение/создание/реконструкция/модернизация (ВПО 207012)/Ремонтно-восстановительные работы (ВПО 204962) | M28: Филиал
A29: 01.0311 | B29: Мероприятия в отношении оборудования автоматической передачи метеорологической и полетной информации | C29: Оборудование автоматической передачи метеорологической и полетной информации (АТИС/ВОЛМЕТ) | D29: Х | E29: Х | F29: Создание/Проектирование/Приобретение/Поставка/МиПНР/ПСИ/Оснащение/Модернизация/Реконструкция - основные этапы | G29: Создание/Проектирование/Приобретение/Поставка/МиПНР/ПСИ/Оснащение/Модернизация/Реконструкция - основные этапы | H29: Х | I29: Х | J29: Ремонтно-восстановительные работы, поддержание эксплуатационной готовности, выполнение работ по бюллетеням, закупка ЗИП, сервисное сопровождение | K29: Исследования, связанные с созданием, внедрением, применением (эксплуатацией) и модернизацией объектов, средств, систем | L29: Создание/Приобретение/Модернизация/Реконструкция - вспомогательные этапы (ВПО 20701)/Ремонтно-восстановительные работы (ВПО 204962) | M29: Дирекция стратегического развития, эксплуатации и технической политики ГД Филиал
A30: 02.0000 | B30: Наблюдение
A31: 02.0100 | B31: Мероприятия в отношении комплексов средств наблюдения
A32: 02.0110 | B32: Мероприятия в отношении средств наблюдения за полетами воздушных судов в районах аэродромов
A33: 02.0111 | B33: Мероприятия в отношении ОРЛ-А | C33: АРЛК, ОРЛ-А | D33: Х | E33: Х | F33: Создание/Проектирование/Строительство/Приобретение/Поставка/МиПНР/ПСИ/Оснащение/Модернизация/Реконструкция - основные этапы | G33: Создание/Проектирование/Строительство/Приобретение/Поставка/МиПНР/ПСИ/Оснащение/Модернизация/Реконструкция - основные этапы | H33: Х | I33: Х | J33: Ремонтно-восстановительные работы, поддержание эксплуатационной готовности, выполнение работ по бюллетеням, закупка ЗИП, сервисное сопровождение | K33: Исследования, связанные с созданием, внедрением, применением (эксплуатацией) и модернизацией объектов, средств, систем | L33: Создание/Приобретение/Модернизация/Реконструкция - вспомогательные этапы (ВПО 20701)/Ремонтно-восстановительные работы (ВПО 204962) | M33: Дирекция стратегического развития, эксплуатации и технической политики/Дирекция по инфраструктуре ГД/Филиал
A34: 02.0112 | B34: Мероприятия в отношении РЛС ОЛП | C34: РЛС ОЛП | D34: Х | E34: Х | F34: Создание/Проектирование/Строительство/Приобретение/Поставка/МиПНР/ПСИ/Оснащение/Модернизация/Реконструкция - основные этапы | G34: Создание/Проектирование/Строительство/Приобретение/Поставка/МиПНР/ПСИ/Оснащение/Модернизация/Реконструкция - основные этапы | H34: Х | I34: Х | J34: Ремонтно-восстановительные работы, поддержание эксплуатационной готовности, выполнение работ по бюллетеням, закупка ЗИП, сервисное сопровождение | K34: Исследования, связанные с созданием, внедрением, применением (эксплуатацией) и модернизацией объектов, средств, систем | L34: Создание/Приобретение/Модернизация/Реконструкция - вспомогательные этапы (ВПО 20701)/Ремонтно-восстановительные работы (ВПО 204962) | M34: Дирекция стратегического развития, эксплуатации и технической политики/Дирекция по инфраструктуре ГД/Филиал
A35: 02.0113 | B35: Мероприятия в отношении АРП | C35: АРП | D35: Х | E35: Х | F35: Создание/Проектирование/Строительство/Приобретение/Поставка/МиПНР/ПСИ/Оснащение/Модернизация/Реконструкция - основные этапы | G35: Создание/Проектирование/Строительство/Приобретение/Поставка/МиПНР/ПСИ/Оснащение/Модернизация/Реконструкция - основные этапы | H35: Х | I35: Х | J35: Ремонтно-восстановительные работы, поддержание эксплуатационной готовности, выполнение работ по бюллетеням, закупка ЗИП, сервисное сопровождение | K35: Исследования, связанные с созданием, внедрением, применением (эксплуатацией) и модернизацией объектов, средств, систем | L35: Создание/Приобретение/Модернизация/Реконструкция - вспомогательные этапы (ВПО 20701)/Ремонтно-восстановительные работы (ВПО 204962) | M35: Дирекция стратегического развития, эксплуатации и технической политики/Дирекция по инфраструктуре ГД/Филиал
A36: 02.0114 | B36: Мероприятия в отношении МПСН-А | C36: МПСН-А | D36: Х | E36: Х | F36: Создание/Проектирование/Приобретение/Поставка/МиПНР/ПСИ/Оснащение/Модернизация/Реконструкция - основные этапы | G36: Создание/Проектирование/Приобретение/Поставка/МиПНР/ПСИ/Оснащение/Модернизация/Реконструкция - основные этапы | H36: Х | I36: Х | J36: Ремонтно-восстановительные работы, поддержание эксплуатационной готовности, выполнение работ по бюллетеням, закупка ЗИП, сервисное сопровождение | K36: Исследования, связанные с созданием, внедрением, применением (эксплуатацией) и модернизацией объектов, средств, систем | L36: Создание/Приобретение/Модернизация/Реконструкция - вспомогательные этапы (ВПО 20701)/Ремонтно-восстановительные работы (ВПО 204962) | M36: Дирекция стратегического развития, эксплуатации и технической политики ГД Филиал
A37: 02.0120 | B37: Мероприятия в отношении средств наблюдения за полетами воздушных судов на воздушных трассах
A38: 02.0121 | B38: Мероприятия в отношении ВРЛ, ОРЛ-Т, ТРЛК | C38: ВРЛ, ОРЛ-Т | D38: Х | E38: Х | F38: Х | G38: Создание/Проектирование/Строительство/Приобретение/Поставка/МиПНР/ПСИ/Оснащение/Модернизация/Реконструкция - основные этапы | H38: Х | I38: Х | J38: Ремонтно-восстановительные работы, поддержание эксплуатационной готовности, выполнение работ по бюллетеням, закупка ЗИП, сервисное сопровождение | K38: Исследования, связанные с созданием, внедрением, применением (эксплуатацией) и модернизацией объектов, средств, систем | L38: Создание/Приобретение/Модернизация/Реконструкция - вспомогательные этапы (ВПО 20701)/Ремонтно-восстановительные работы (ВПО 204962) | M38: Дирекция стратегического развития, эксплуатации и технической политики/Дирекция по инфраструктуре ГД/Филиал
A39: 02.0122 | B39: Мероприятия в отношении АЗН-В | C39: АЗН-В, АЗН, СК АЗН-В | D39: Х | E39: Х | F39: Создание/Проектирование/Приобретение/Поставка/МиПНР/ПСИ/Оснащение/Модернизация/Реконструкция - основные этапы | G39: Создание/Проектирование/Приобретение/Поставка/МиПНР/ПСИ/Оснащение/Модернизация/Реконструкция - основные этапы | H39: Х | I39: Х | J39: Ремонтно-восстановительные работы, поддержание эксплуатационной готовности, выполнение работ по бюллетеням, закупка ЗИП, сервисное сопровождение | K39: Исследования, связанные с созданием, внедрением, применением (эксплуатацией) и модернизацией объектов, средств, систем | L39: Создание/Приобретение/Модернизация/Реконструкция - вспомогательные этапы (ВПО 20701)/Ремонтно-восстановительные работы (ВПО 204962) | M39: Дирекция стратегического развития, эксплуатации и технической политики ГД Филиал
A40: 02.0123 | B40: Мероприятия в отношении МПСН-Ш | C40: МПСН-Ш | D40: Х | E40: Создание/Проектирование/Приобретение/Поставка/МиПНР/ПСИ/Оснащение/Модернизация/Реконструкция - основные этапы | F40: Х | G40: Создание/Проектирование/Приобретение/Поставка/МиПНР/ПСИ/Оснащение/Модернизация/Реконструкция - основные этапы | H40: Х | I40: Х | J40: Ремонтно-восстановительные работы, поддержание эксплуатационной готовности, выполнение работ по бюллетеням, закупка ЗИП, сервисное сопровождение | K40: Исследования, связанные с созданием, внедрением, применением (эксплуатацией) и модернизацией объектов, средств, систем | L40: Создание/Приобретение/Модернизация/Реконструкция - вспомогательные этапы (ВПО 20701)/Ремонтно-восстановительные работы (ВПО 204962) | M40: Дирекция стратегического развития, эксплуатации и технической политики ГД Филиал
A41: 02.0124 | B41: Мероприятия в отношении HMU, AHMS | C41: HMU, AHMS | D41: X | E41: Х | F41: Х | G41: Создание/Проектирование/Приобретение/Поставка/МиПНР/ПСИ/Оснащение/Модернизация/Реконструкция - основные этапы | H41: X | I41: X | J41: Ремонтно-восстановительные работы, поддержание эксплуатационной готовности, выполнение работ по бюллетеням, закупка ЗИП, сервисное сопровождение | K41: Исследования, связанные с созданием, внедрением, применением (эксплуатацией) и модернизацией объектов, средств, систем | L41: Ремонтно-восстановительные работы (ВПО 204962) | M41: Дирекция стратегического развития, эксплуатации и технической политики ГД Филиал
A42: 02.0200 | B42: Мероприятия в отношении прочих средств наблюдения
...

Sheet Пр 2б Структура планов
D1: ПРИЛОЖЕНИЕ № 2 б
D2: К ПОРЯДКУ ТЕКУЩЕГО ПЛАНИРОВАНИЯ ПРОИЗВОДСТВЕННО-ХОЗЯЙСТВЕННОЙ ДЕЯТЕЛЬНОСТИ ФГУП «ГОСКОРПОРАЦИЯ ПО ОрВД»
A4: Структура планов ФГУП "Госкорпорация по ОрВД" 3 группы
A5: № п/п | B5: Разделы, подразделы плана | C5: Централизованные планы 3 группы | F5: Децентрализованные планы ПДФ
C6: №301.1 Централизованный план мероприятий по поисково-спасательному обеспечению в части дежурства поисково-спасательных воздушных судов и экипажей и выполнение дежурными экипажами тренировочных полетов ФГУП «Госкорпорация по ОрВД» на 20____ год | D6: №302.1 | E6: №303.1 | F6: ВПО ПДФ
A7: 1. | B7: 2. | C7: 3. | D7: 4. | E7: 5. | F7: 6.
C8: текущие
C9: 20302
A10: 23.0000 | B10: Поисково-спасательное обеспечение в части дежурства поисково-спасательных воздушных судов и экипажей и выполнение дежурными экипажами тренировочных полетов
A11: 23.0100 | B11: Мероприятия по поисково-спасательному обеспечению в части дежурства поисково-спасательных воздушных судов и экипажей и выполнению дежурными экипажами тренировочных полетов | C11: Все мероприятия

Sheet Пр 2в Структура планов
D1: ПРИЛОЖЕНИЕ № 2 в
D2: К ПОРЯДКУ ТЕКУЩЕГО ПЛАНИРОВАНИЯ ПРОИЗВОДСТВЕННО-ХОЗЯЙСТВЕННОЙ ДЕЯТЕЛЬНОСТИ ФГУП «ГОСКОРПОРАЦИЯ ПО ОрВД»
A4: Структура планов ФГУП "Госкорпорация по ОрВД" 4 группы
A5: № п/п | B5: Разделы, подразделы плана | C5: Централизованные планы 4 группы | F5: Децентрализованные планы ПДФ
C6: 4.1. Централизованный план профессиональной подготовки | D6: 4.2. Централизованный план мероприятий социальной программы | E6: 4.3. Централизованный План международных и корпоративных мероприятий | F6: ВПО ПДФ
A7: 1. | B7: 2. | C7: 3. | D7: 4. | E7: 5. | F7: 6.
A8: 20.0000 | B8: Профессиональная подготовка и переподготовка
A9: 20.0100 | B9: Целевое обучение | C9: Все мероприятия | D9: Х | E9: Х
A10: 20.0200 | B10: Первоначальная подготовка (ускоренные курсы) | C10: Все мероприятия | D10: Х | E10: Х
A11: 20.0300 | B11: Расходы на организацию и проведение конкурсов профессионального мастерства | C11: Проведение финалов конкурсов, участие в международных конкурсах | D11: Х | E11: Х | F11: Проведение конкурсов профмастерства филиалов
A12: 20.0400 | B12: Расходы на обучение в Институте аэронавигации | C12: Все мероприятия | D12: Х | E12: Х | F12: Х
A13: 20.0600 | B13: Обучение работников, включенных в кадровый резерв Предприятия | C13: Все мероприятия | D13: Х | E13: Х | F13: Х
A14: 20.0700 | B14: Профессиональная подготовка и переподготовка | C14: Обучение работников предприятия | D14: Х | E14: Х | F14: Обучение работников филиала
A15: 20.0900 | B15: Прочее обучение | C15: Х | D15: Х | E15: Х | F15: Обучение работников филиала
A16: 21.0000 | B16: Социальная программа
A17: 21.0100 | B17: Жилищная программа Предприятия | C17: Х | D17: Все мероприятия | E17: Х | F17: Х
A18: 21.0200 | B18: Добровольное коллективное страхование от потери профессиональной трудоспособности, несчастных случаев и болезней | C18: Х | D18: Все мероприятия | E18: Х | F18: Х
A19: 21.0300 | B19: Санаторно-курортное лечение | C19: Х | D19: По централизованной программе | E19: Х | F19: Прочее
A20: 21.0400 | B20: Спортивные мероприятия | C20: Х | D20: Международные и корпоративные спортивные мероприятия | E20: Х | F20: Спортивные мероприятия филиала
A21: 21.0500 | B21: Негосударственное пенсионное обеспечение | C21: Х | D21: Все мероприятия | E21: Х | F21: Х
A22: 21.0600 | B22: Программа по привлечению и закреплению работников служб движения и служб ЭРТОС в отдельных структурных подразделениях филиалов ФГУП «Госкорпорация по ОрВД», расположенных в районах Дальнего Востока, Крайнего Севера и приравненных к ним местностях | C22: Х | D22: Все мероприятия | E22: Х | F22: Х
A23: 21.0700 | B23: Прочие расходы по коллективному договору | C23: Х | D23: Х | E23: Х | F23: Все мероприятия
A24: 21.0800 | B24: Социальные расходы по трудовым договорам и законодательству | C24: Х | D24: Х | E24: Х | F24: Все мероприятия
A25: 22.0000 | B25: Международные и корпоративные мероприятия
A26: 22.0100 | B26: Международные мероприятия | C26: Х | D26: Х | E26: Все мероприятия | F26: Х
A27: 22.0200 | B27: Корпоративные мероприятия | C27: Х | D27: Х | E27: Мероприятия по централизованной программе | F27: Мероприятия филиала
A28: 22.0300 | B28: Выставки | C28: Х | D28: Х | E28: Все мероприятия | F28: Х
A29: 22.0400 | B29: Участие в форумах, семинарах, конференциях, круглых столах и др. | C29: Х | D29: Х | E29: Мероприятия по централизованной программе | F29: Мероприятия филиала
A30: 22.0500 | B30: Членские взносы | C30: Х | D30: Х | E30: Все | F30: Х

Sheet Пр 3 заявка 1- 3
BB1: ПРИЛОЖЕНИЕ № 3
BB2: К ПОРЯДКУ ТЕКУЩЕГО ПЛАНИРОВАНИЯ ПРОИЗВОДСТВЕННО-ХОЗЯЙСТВЕННОЙ ДЕЯТЕЛЬНОСТИ ФГУП «ГОСКОРПОРАЦИЯ ПО ОрВД»
AE3: Форма заявки на мероприятия в планы 1 - 3 группы (кроме планов подгрупп 104.1, 105.1, 201.1)
AD5: ФГУП «Госкорпорация по ОрВД»
AB6: (включая корректировку № ________от _______)
AY7: тыс. руб.
A8: КИП | B8: НД | C8: КМ | D8: Год инициации | E8: Порядковый номер | F8: Код инпициатора мероприятия =1-ГК, =2-филиал | G8: Код Плана (Пр. 1) | H8: Территориальный код этапа мероприятия | I8: Код места установки | J8: Объект, средство, система | K8: Тип этапа (Пр. 27) | L8: Порядковый номер этапа мероприятия | M8: Номер раздела/подраздела (Пр 2а) | N8: Статья ВПО | O8: КУУ | P8: КВУ | Q8: Филиал | R8: Номер УИПа (справочник) | S8: Номер показателя ПДП (справочник) | T8: Наименование показателя Ипр (справочник) | U8: Номер поручения ФОИВ (справочник) | V8: Признак инновационности мероприятия (да/нет) | W8: Относится к Стратегии цифровой трансформации (да/нет) | X8: Статус мероприятия (закрыто/исполняется) | Y8: Наименование мероприятия | Z8: Наименование этапа | AA8: Место реализации | AB8: Наименование оборудования / ОС / НМА | AC8: Объект, средство, система | AD8: Общая плановая стоимость мероприятия/этапа | AE8: Срок начала реализации мероприятия/этапа (мм_гггг, мм-месяц, гггг-год) | AF8: Срок завершения реализации мероприятия/этапа (мм_гггг, мм-месяц, гггг-год) | AG8: Выполнено по состоянию на 01.01.____ | AH8: Оплачено по состоянию на 01.01.____ | AI8: Централизованное финансирование по состоянию на 01.01.____ | AJ8: Платежи текущего финансового года | AW8: Платежи последующих периодов | AZ8: Планируемая дата заключения договора (мм_гггг, мм - месяц, гггг - год | BA8: Реквизиты договора | BC8: Ответственный исполнитель в филиале | BD8: Ответственный исполнитель ГД | BE8: Передано на исполнение в филиал (дата и номер Распоряжения) | BF8: Обеспечение финансированием в планируемом году-1, опцион -0 | BG8: Обеспечение финансированием в планируемом году-1, опцион -1
AJ9: 1 кв-л по оплате | AM9: 2 кв-л по оплате | AP9: 3 кв-л по оплате | AS9: 4 кв-л по оплате | AV9: Итого | AW9: 1-й плановый год | AX9: 2-й плановый год | AY9: последующие годы | BA9: Номер / Планируемый ** | BB9: Дата /Планируемый**
D10: ОО | E10: YYYY | F10: К | G10: XXX.X | H10: FFFF | I10: BBB | J10: CCC | K10: GG | L10: HH | M10: DD.EEEE | AJ10: январь | AK10: февраль | AL10: март | AM10: апрель | AN10: май | AO10: июнь | AP10: июль | AQ10: август | AR10: сентябрь | AS10: октябрь | AT10: ноябрь | AU10: декабрь
A11: * | B11: * | C11: * | D11: * | E11: * | F11: * | G11: * | H11: * | I11: * | J11: * | K11: * | L11: * | M11: * | N11: * | O11: * | P11: * | Q11: * | R11: * | S11: * | T11: * | U11: * | V11: * | W11: * | X11: * | Y11: 1 | Z11: 2 | AA11: 3 | AB11: 4 | AC11: 5 | AD11: 6 | AE11: 7 | AF11: 8 | AG11: 9 | AH11: 10 | AI11: 11 | AJ11: 12 | AK11: 13 | AL11: 14 | AM11: 15 | AN11: 16 | AO11: 17 | AP11: 18 | AQ11: 19 | AR11: 20 | AS11: 21 | AT11: 22 | AU11: 23 | AV11: 24 | AW11: 25 | AX11: 26 | AY11: 27 | AZ11: 28 | BA11: 29 | BB11: 30 | BC11: 31 | BD11: 32 | BE11: 33 | BF11: 34 | BG11: 35
R12: Наблюдение (УИП 2) | S12: выбор из выпадающего списка | T12: выбор из выпадающего списка | U12: выбор из выпадающего списка
R13: Наблюдение (УИП 2) | S13: Раздел | T13: Раздел | U13: Раздел | V13: Раздел
R14: Наблюдение (УИП 2) | S14: выбор из выпадающего списка | T14: выбор из выпадающего списка | U14: выбор из выпадающего списка
R15: Хоз деятельность (УИП 6 Прочее) | S15: Подраздел | T15: Подраздел | U15: Подраздел | V15: Подраздел
S16: выбор из выпадающего списка | T16: выбор из выпадающего списка | U16: выбор из выпадающего списка
S17: выбор из выпадающего списка | T17: выбор из выпадающего списка | U17: выбор из выпадающего списка
S18: выбор из выпадающего списка | T18: выбор из выпадающего списка | U18: выбор из выпадающего списка
A19: Примечание:
A20: Колонки (1)-(35) для печатной формы плана
A21: Колонки (1)-(35),(*) - для электронной формы плана
A22: В случае проставления признака "да" в колонке "Относится к Стратегии цифровой трансформации (да/нет)" заполнятся приложение к Приложению № 3
Z23: ОН - мероприятия общего назначения (АНО), ПД - мероприятия по прочим видам деятельности.

Sheet Приложение к Пр 3 заявка 1-3
Y1: ПРИЛОЖЕНИЕ К ПРИЛОЖЕНИЮ № 3
Y2: К ПОРЯДКУ ТЕКУЩЕГО ПЛАНИРОВАНИЯ ПРОИЗВОДСТВЕННО-ХОЗЯЙСТВЕННОЙ ДЕЯТЕЛЬНОСТИ ФГУП «ГОСКОРПОРАЦИЯ ПО ОрВД»
A3: Приложение к форме заявки на мероприятия в планы 1 - 3 группы (кроме планов подгрупп 104.1, 105.1, 201.1) *
AI4: тыс. рублей
A5: № п/п | B5: КМ | C5: № инициативы СЦТ | D5: Код мероприятия | E5: Наименование мероприятия | F5: Номер договора и дата/планируемый | G5: Стоимость мероприятия (этапа) планируемая | H5: Лимит финансирования на ____ год, в т.ч. | I5: Текущий год | O5: Платежи последующих периодов
O6: 1-й плановый год | V6: 2-й плановый год | AC6: последующие годы
I7: Ключевые показатели эффективности (КПЭ) цифровой трансформации** | O7: Итого | P7: Ключевые показатели эффективности (КПЭ) цифровой трансформации** | V7: Итого | W7: Ключевые показатели эффективности (КПЭ) цифровой трансформации** | AC7: Итого | AD7: Ключевые показатели эффективности (КПЭ) цифровой трансформации**
I8: КПЭ 17 | J8: КПЭ 23 | K8: КПЭ 19 | L8: КПЭ 26 | M8: КПЭ 20 | N8: КПЭ 22 | P8: КПЭ 17 | Q8: КПЭ 23 | R8: КПЭ 19 | S8: КПЭ 26 | T8: КПЭ 20 | U8: КПЭ 22 | W8: КПЭ 17 | X8: КПЭ 23 | Y8: КПЭ 19 | Z8: КПЭ 26 | AA8: КПЭ 20 | AB8: КПЭ 22 | AD8: КПЭ 17 | AE8: КПЭ 23 | AF8: КПЭ 19 | AG8: КПЭ 26 | AH8: КПЭ 20 | AI8: КПЭ 22
A9: 1 | C9: 2 | D9: 3 | E9: 4 | F9: 5 | G9: 6 | H9: 7 | I9: 8 | J9: 9 | K9: 11 | L9: 12 | M9: 13 | N9: 14 | O9: 15 | P9: 16 | Q9: 17 | R9: 19 | S9: 20 | T9: 21 | U9: 22 | V9: 23 | W9: 24 | X9: 25 | Y9: 27 | Z9: 28 | AA9: 29 | AB9: 30 | AC9: 31 | AD9: 32 | AE9: 33 | AF9: 35 | AG9: 36 | AH9: 37 | AI9: 38
A10: 1 | C10: 1 | E10: Мероприятие 1 | F10: № ___ от _____ | G10: =H10+O10+V10+AC10 -> 500000 | H10: =SUM(I10:N10) -> 100000 | I10: =SUM(I11:I15) -> 30000 | J10: 20000 | K10: =SUM(K11:K15) -> 30000 | L10: =SUM(L11:L15) -> 20000 | M10: =SUM(M11:M15) -> 0 | N10: =SUM(N11:N15) -> 0 | O10: =SUM(P10:U10) -> 100000 | P10: =SUM(P11:P15) -> 30000 | Q10: =SUM(Q11:Q15) -> 20000 | R10: =SUM(R11:R15) -> 30000 | S10: =SUM(S11:S15) -> 20000 | T10: =SUM(T11:T15) -> 0 | U10: =SUM(U11:U15) -> 0 | V10: =SUM(W10:AB10) -> 100000 | W10: =SUM(W11:W15) -> 30000 | X10: =SUM(X11:X15) -> 20000 | Y10: =SUM(Y11:Y15) -> 30000 | Z10: =SUM(Z11:Z15) -> 20000 | AA10: =SUM(AA11:AA15) -> 0 | AB10: =SUM(AB11:AB15) -> 0 | AC10: =SUM(AD10:AI10) -> 200000 | AD10: =SUM(AD11:AD15) -> 0 | AE10: =SUM(AE11:AE15) -> 0 | AF10: =SUM(AF11:AF15) -> 100000 | AG10: =SUM(AG11:AG15) -> 100000 | AH10: =SUM(AH11:AH15) -> 0 | AI10: =SUM(AI11:AI15) -> 0
C11: 1 | E11: Код ОКПД2 | I11: 30000 | P11: 30000 | W11: 30000
C12: 1 | E12: Код ОКПД2 | J12: 20000 | Q12: 20000 | X12: 20000
C13: 1 | E13: Код ОКПД2 | K13: 20000 | R13: 30000 | AF13: 100000
C14: 1 | E14: Код ОКПД2 | K14: 10000 | Y14: 30000
C15: 1 | E15: Код ОКПД2 | L15: 20000 | S15: 20000 | Z15: 20000 | AG15: 100000
A16: 2 | C16: 3 | E16: Мероприятие 2 | F16: Планируемый | G16: =H16+O16+V16+AC16 -> 30000 | H16: =SUM(H17) -> 30000 | I16: =SUM(I17) -> 0 | K16: 0 | M16: 0 | N16: =SUM(N17) -> 30000 | O16: =SUM(P16:U16) -> 0 | P16: =SUM(P17) -> 0 | R16: =SUM(R17) -> 0 | T16: =SUM(T17) -> 0 | U16: =SUM(U17) -> 0 | V16: =W16+Y16+AA16+AB16 -> 0 | W16: =SUM(W17) -> 0 | Y16: =SUM(Y17) -> 0 | AA16: =SUM(AA17) -> 0 | AB16: =SUM(AB17) -> 0 | AC16: =SUM(AD16:AI16) -> 0 | AD16: =SUM(AD17) -> 0 | AF16: =SUM(AF17) -> 0 | AH16: =SUM(AH17) -> 0 | AI16: =SUM(AI17) -> 0
C17: 3 | E17: Код ОКПД2 | G17: =H17+O17+V17+AC17 -> 30000 | H17: =I17+K17+M17+N17 -> 30000 | I17: 0 | K17: 0 | M17: 0 | N17: 30000 | O17: =SUM(P17:U17) -> 0 | P17: 0 | R17: 0 | T17: 0 | U17: 0 | V17: 0 | W17: 0 | Y17: 0 | AA17: 0 | AB17: 0 | AC17: 0 | AD17: 0 | AF17: 0 | AH17: 0 | AI17: 0
A18: 3 | C18: 6 | E18: Мероприятие 3 | F18: Планируемый | G18: =H18+O18+V18+AC18 -> 200000 | H18: =I18+K18+M18+N18 -> 70000 | I18: =SUM(I19) -> 0 | K18: =SUM(K19) -> 0 | M18: =SUM(M19) -> 70000 | N18: =SUM(N19) -> 0 | O18: =P18+R18+T18+U18 -> 100000 | P18: =SUM(P19) -> 100000 | R18: =SUM(R19) -> 0 | T18: =SUM(T19) -> 0 | U18: =SUM(U19) -> 0 | V18: 30000 | W18: =SUM(W19) -> 0 | Y18: =SUM(Y19) -> 0 | AA18: =SUM(AA19) -> 0 | AB18: =SUM(AB19) -> 0 | AC18: =AD18+AF18+AH18+AI18 -> 0 | AD18: =SUM(AD19) -> 0 | AF18: =SUM(AF19) -> 0 | AH18: =SUM(AH19) -> 0 | AI18: =SUM(AI19) -> 0
C19: 6 | E19: Код ОКПД2 | G19: =H19+O19+V19+AC19 -> 170000 | H19: =I19+K19+M19+N19 -> 70000 | I19: 0 | K19: 0 | M19: 70000 | N19: 0 | O19: =P19+R19+T19+U19 -> 100000 | P19: 100000 | R19: 0 | T19: 0 | U19: 0 | V19: =W19+Y19+AA19+AB19 -> 0 | W19: 0 | Y19: 0 | AA19: 0 | AB19: 0 | AC19: =AD19+AF19+AH19+AI19 -> 0 | AD19: 0 | AF19: 0 | AH19: 0 | AI19: 0
A20: N
A22: * Приложение заполняется только в том случае , если мероприятие относится к Стратегии цифровой трансформации (СЦТ)
A23: ** Определяются в соответствии с общероссийским классификатором по видам экономической деятельности (ОКПД2).
A24: В гр.2 указывается № инициативы СЦТ в соответсвии с утвержденной СЦТ ФГУП «Госкорпорация по ОрВД» до 2030 года и действующей редакцией методических рекомендаций по цифровой трансформации государственных корпораций и компаний с государственным участием (приложение №3)
A25: Сумма КПЭ: по гр. 8-14 должна быть равна лимиту финансирования текущего года, отраженному в гр. 7; по гр. 16-22 должна быть равна лимиту 1-го планового года, отраженному в гр. 15; по гр. 24-30 должна быть равна лимиту 2-го планового года, отраженному в гр. 23; по гр. 32-38 должна быть равна лимиту последующих годов, отраженному в гр. 31;
A26: Гр. 6 равна сумме гр. 7, 15,23,31
A27: В гр. 8; гр. 16; гр. 24; гр.32 (КПЭ 17 -"Увеличение вложений в российские решения в сфере информационных технологий")- указывается объем расходов на российское ПО, включенное в Единый реестр российских программ для электронных вычислительных машин и баз данных или в Единый реестр программ для электронных вычислительных машин и баз данных государств - членов Евразийского экономического союза, и связанные с ним работы (услуги). В случае если ПО является свободно распространяемым, но сведения о таком программном обеспечении не включены в Единый реестр российского ПО, то такое ПО относится к иностранному ПО и заполняются гр. 9; гр. 17; гр. 25; гр.33 в соответствующем периоде;
A28: В гр. 9, гр.17, гр. 25, гр. 33 (КПЭ 23 " Увеличение расходов на информационные технологии") - указывается объем расходов на иностранное ПО и связанные с ним работы (услуги).
A29: В гр. 11; гр. 19; гр. 27; гр.35 (КПЭ 19 "Увеличение вложений в радиоэлектронную продукцию российского происхождения, в том числе в телекоммуникационное оборудование и программно-аппаратные комплексы"- указывается объем расходов государственной компании на радиоэлектронную продукцию российского происхождения, в том числе телекоммуникационное оборудование и программно-аппаратные комплексы. Под радиоэлектронной продукцией российского происхождения понимается радиоэлектронная продукция, сведения о которой включены в реестр российской промышленной продукции (согласно постановлению Правительства Российской Федерации от 17.07.2015 N 719). Также включаются расходы на радиоэлектронную продукцию, которая включена в евразийский реестр промышленных товаров государств - членов Евразийского экономического союза. В данные графы не включаются расходы на работы (услуги), связанные с радиоэлектронной продукцией. Указанные затраты отражаются в гр. 12,гр.20,гр.28, гр. 36 в соответствующем периоде.
A30: В гр. 12; гр. 20; гр. 28; гр.36 (КПЭ 26 "Увеличение расходов, направленных на закупку радиоэлектронной продукции, телекоммуникационного оборудования и программно-аппаратных комплексов, а также связанных с ней работ (услуг)") - указывается объем расходов государственной компании на радиоэлектронную продукцию иностранного производства, в том числе телекоммуникационное оборудование и программно-аппаратные комплексы, а также связанные с ней работы (услуги), а также работы (услуги) связанные с приобретением радиоэлектронной продукции российского производства.
A31: В гр. 13; гр. 21; гр. 29; гр.37 (КПЭ 20 "Объем затрат на исследования и разработки, направленных на создание и развитие передовых и критически важных для отрасли цифровых технологий и решений, в том числе новых производственных технологий, связанных с интенсивным применением информационно-коммуникационных технологий в рамках реализации инициатив (проектов) СЦТ") - указывается объем затрат на научные исследования и разработки (НИОКР), направленных на создание и развитие передовых и критически важных для отрасли цифровых технологий и решений, в том числе новых производственных технологий, связанных с интенсивным применением информационно-коммуникационных технологий.
A32: В гр. 13; гр. 21; гр. 29; гр.37 (КПЭ 22 "Объем расходов государственных компаний на реализацию инициатив (мероприятий), связанных с созданием, внедрением и применением технологий и решений в сфере искусственного интеллекта") - указываются расходы связанные с технологиями и решениями в сфере искусственного интеллекта.

Sheet Пр.3.2 заявка в Пл.НИОКР 
E1: ПРИЛОЖЕНИЕ № 3.2.
E2: К ПОРЯДКУ ТЕКУЩЕГО ПЛАНИРОВАНИЯ ПРОИЗВОДСТВЕННО-ХОЗЯЙСТВЕННОЙ ДЕЯТЕЛЬНОСТИ ФГУП «ГОСКОРПОРАЦИЯ ПО ОрВД»
A3: Заявка на включение мероприятия в План научно-исследовательских и опытно-конструкторских работ ФГУП "Госкорпорация по ОрВД" на 20___ год из Перечня тематик (Приложение к Плану НИОКР на ___ год)
A5: 1. Данные по работе в форму Плана НИОКР:
A7: 1.1. Наименование темы:
A9: 1.2. Наименование раздела, подраздела Плана НИОКР:
A11: 1.3. Структурное подразделение, ответственное за сопровождение работы, ФИО ответственного за сопровождение работы:
A13: 1.4. Период выполнения работы (сроки реализации мероприятия): | G13: год (годы)
A14: Срок начала реализации мероприятия | G14: месяц, год
A15: Срок завершения реализации мероприятия | G15: месяц, год
A17: 1.5. Результаты работы, этапа:
A19: 1.6. Объем финансирования:
B20: общий: | D20: тыс. руб.
B21: 20___ г.: | D21: тыс. руб.
B22: 20___ г.: | D22: тыс. руб.
B23: 20___ г.: | D23: тыс. руб.
A25: 2. Цель работы:
A27: 3. Краткое описание работы:
A29: 4. Ожидаемые результаты:
A31: 5. Этапность выполнения работ (указать количество этапов):
A33: № этапа | B33: Содержание работ по этапу | E33: Стоимость этапа (тыс. руб.) | G33: Период выполнения | I33: Отчетность по этапу
E34: (тыс. руб.) | F34: % от общей стоимости мероприятия | G34: Начало | H34: Окончание (Х + __ мес)
A38: Х -
A39: Условия оплаты (в соответствии с описанием предмета закупки):
A41: 6. Примечание:
A43: 7. Принадлежность к стратегии цифровой трансформации (да/нет)**
A45: 8. Планируемый срок заключения договора (месяц, год):
A47: 9. Приложение: | C47: 1. Проект технического задания, согласованный Росавиацией, на ___ л. 2. Служебная записка дирекции ЦОЗД о размере лимитной стоимости мероприятия для целей включения мероприятия в План НИОКР из Перечня тематик НИОКР, на ___ л.
A49: Директор по направлению деятельности:
A52: Руководитель структурного подразделения:
A55: Ответственный за сопровождение НИР от структурного подразделения:
A58: Дата:
B61: * | C61: Актуальные формы для заполнения сетевых графиков Корпоративном портале: Документы предприятия/Регламенты и стандарты/Общекорпоративные документы СМК/СТО-ГК-0001-017 Текущее экономическое планирование»
B62: ** В случае проставления признака "да" заполнятся приложение к Приложению № 3

Sheet Пр3.1.Заявка в Перечень тем
E1: ПРИЛОЖЕНИЕ № 3.1.
E2: К ПОРЯДКУ ТЕКУЩЕГО ПЛАНИРОВАНИЯ ПРОИЗВОДСТВЕННО-ХОЗЯЙСТВЕННОЙ ДЕЯТЕЛЬНОСТИ ФГУП «ГОСКОРПОРАЦИЯ ПО ОрВД»
A3: Заявка на включение новой работы в Перечень тематик НИОКР (Приложение к Плану научно-исследовательских и опытно-конструкторских работ ФГУП "Госкорпорация по ОрВД" на 20___ год)
A5: 1. Данные по работе в форму Плана НИОКР:
A7: 1.1. Наименование темы:
A9: 1.2. Наименование раздела, подраздела Плана НИОКР:
A11: 1.3. Структурное подразделение, ответственное за сопровождение работы, ФИО ответственного за сопровождение работы:
A13: 1.4. Период выполнения работы (сроки реализации мероприятия): | G13: год (годы)
A14: Срок начала реализации мероприятия | G14: месяц, год
A15: Срок завершения реализации мероприятия | G15: месяц, год
A17: 1.5. Результаты работы, этапа:
A19: 1.6. Объем финансирования:
B20: общий: | D20: тыс. руб.
B21: 20___ г.: | D21: тыс. руб.
B22: 20___ г.: | D22: тыс. руб.
B23: 20___ г.: | D23: тыс. руб.
A25: 2. Цель работы:
A27: 3. Краткое описание работы:
A29: 4. Ожидаемые результаты:
A31: 5. Этапность выполнения работ (указать количество этапов):
A33: № этапа | B33: Содержание работ по этапу | E33: Стоимость этапа | G33: Период выполнения | I33: Отчетность по этапу
E34: (тыс. руб.) | F34: % от общей стоимости мероприятия | G34: Начало (месяц, год) | H34: Окончание (Х + __ мес)
A38: Х -
A40: 6. Примечание:
A42: 7. Планируемый срок заключения договора (месяц, год):
A44: 8. Приложение: | C44: 1. Обоснование необходимости выполнения работы, на ___ л. 2. Обоснование ориентировочной лимитной стоимости мероприятия, согласованное дирекцией ЦОЗД, на ___ л.
A46: Директор по направлению деятельности:
A49: Руководитель структурного подразделения:
A52: Ответственный за сопровождение НИР от структурного подразделения:
A55: Дата:
A58: * | B58: Актуальные формы для заполнения сетевых графиков Корпоративном портале: Документы предприятия/Регламенты и стандарты/Общекорпоративные документы СМК/СТО-ГК-0001-017 Текущее экономическое планирование»

Sheet Пр 3.3 заявка Пл. 104.1-201.1
BI1: ПРИЛОЖЕНИЕ № 3.3
BI2: К ПОРЯДКУ ТЕКУЩЕГО ПЛАНИРОВАНИЯ ПРОИЗВОДСТВЕННО-ХОЗЯЙСТВЕННОЙ ДЕЯТЕЛЬНОСТИ ФГУП «ГОСКОРПОРАЦИЯ ПО ОрВД»
AD3: Форма заявки на мероприятия в централизованный план 1- 2 группы подгрупп 104.1, 105.1, 201.1
AH5: ФГУП «Госкорпорация по ОрВД»
AB6: (включая корректировку № ________от _______)
AY7: тыс. руб.
A8: НД | B8: КИП | C8: КМ | D8: Год инициации | E8: Порядковый номер | F8: Код инициатора мероприятия =1-ГК, =2-филиал | G8: Код Плана (Пр. 1) | H8: Территориальный код этапа мероприятия | I8: Код места установки | J8: Объект, средство, система | K8: Тип этапа (Пр. 27) | L8: Порядковый номер этапа мероприятия | M8: Номер раздела/подраздела (Пр 2а) | N8: Статья ВПО | O8: КУУ | P8: КВУ | Q8: Филиал | R8: Номер УИПа (справочник) | S8: Номер показателя ПДП (справочник) | T8: Наименование показателя Ипр (справочник) | U8: Номер поручения ФОИВ (справочник) | V8: Признак инновационности мероприятия (да/нет) | W8: Относится к Стратегии цифровой трансформации (да/нет)* | X8: Статус мероприятия (закрыто/исполняется) | Y8: Наименование мероприятия | Z8: Краткое наименование мероприятия | AA8: Место реализации | AB8: Наименование оборудования / ОС / НМА/Воздушного судна | AC8: Тип этапа / Вид работ | AD8: Срок начала реализации мероприятия/этапа (мм_гггг, мм-месяц, гггг-год) | AE8: Срок завершения реализации мероприятия/этапа (мм_гггг, мм-месяц, гггг-год) | AF8: Реквизиты договора | AH8: Общая плановая стоимость мероприятия/этапа | AI8: Финансирование по договору по состоянию на 01.01.___ | AJ8: Платежи текущего финансового года | AW8: Платежи последующих периодов | AZ8: Планируемая дата заключения договора (мм_гггг, мм - месяц, гггг - год | BA8: Дата выполнения обязательств по договору (мм_гггг ) | BB8: Ответственный исполнитель в филиале | BC8: Ответственный исполнитель ГД | BD8: Передано на исполнение в филиал (дата и номер Распоряжения) | BE8: Обеспечение финансированием в планируемом году-1, опцион -0 | BF8: Проект-аналог/новое (ранее не закупалось) | BG8: Критерии | BJ8: Информация по действующему оборудованию | BO8: Объемы финансирования
AF9: Номер / Планируемый ** | AG9: Дата /Планируемый** | AJ9: 1 кв-л по оплате | AM9: 2 кв-л по оплате | AP9: 3 кв-л по оплате | AS9: 4 кв-л по оплате | AV9: Итого | AW9: 1-й плановый год | AX9: 2-й плановый год | AY9: последующие годы | BG9: Наличие утвержденной ПСД или положительное заключение | BH9: Земля (Кадастровый номер; Номер и дата правоустанавливающие документа; Дата окончания срока предоставления) | BI9: Стадия оформления прав на землю (Если не оформлена) | BJ9: Дата ввода оборудования (дд.мм.гг.) | BK9: Назначенный ресурс (лет) | BL9: Фактический срок службы (лет) | BM9: Из них продление срока службы (лет) | BN9: Обоснование включения (с приложением Акта о техническом состоянии с указанием невозможности продления ресурса)
D10: ОО | E10: YYYY | F10: К | G10: XXX.X | H10: FFFF | I10: BBB | J10: CCC | K10: GG | L10: HH | M10: DD.EEEE | AJ10: январь | AK10: февраль | AL10: март | AM10: апрель | AN10: май | AO10: июнь | AP10: июль | AQ10: август | AR10: сентябрь | AS10: октябрь | AT10: ноябрь | AU10: декабрь | BO10: по состоянию на 01.01.20___ | BP10: 01.01.20__ | BQ10: 01.02.20__ | BR10: 01.03.20__ | BS10: 01.04.20__ | BT10: 01.05.20__ | BU10: 01.06.20__ | BV10: 01.07.20__ | BW10: 01.08.20__ | BX10: 01.09.20__ | BY10: 01.10.20__ | BZ10: 01.11.20__ | CA10: 01.12.20__ | CB10: ИТОГО 20__ | CC10: 202_ | CD10: 202_ | CE10: 202_ | CF10: 202_ | CG10: 202_ | CH10: 202_ | CI10: 203_
A11: 1 | B11: * | C11: * | D11: * | E11: * | F11: * | G11: * | H11: * | I11: * | J11: * | K11: * | L11: * | M11: * | N11: * | O11: * | P11: * | Q11: * | R11: * | S11: * | T11: * | U11: * | V11: * | W11: * | X11: * | Y11: 2 | Z11: * | AA11: 3 | AB11: 4 | AC11: 5 | AD11: 6 | AE11: 7 | AF11: 8 | AG11: 9 | AH11: 10 | AI11: 11 | AJ11: 12 | AK11: 13 | AL11: 14 | AM11: 15 | AN11: 16 | AO11: 17 | AP11: 18 | AQ11: 19 | AR11: 20 | AS11: 21 | AT11: 22 | AU11: 23 | AV11: 24 | AW11: 25 | AX11: 26 | AY11: 27 | AZ11: 28 | BA11: 29 | BB11: 30 | BC11: 31 | BD11: 32 | BE11: 33 | BF11: 34 | BG11: 35 | BH11: 36 | BI11: 37 | BJ11: 38 | BK11: 39 | BL11: 40 | BM11: 41 | BN11: 42 | BO11: * | BP11: * | BQ11: * | BR11: * | BS11: * | BT11: * | BU11: * | BV11: * | BW11: * | BX11: * | BY11: * | BZ11: * | CA11: * | CB11: * | CC11: * | CD11: * | CE11: * | CF11: * | CG11: * | CH11: * | CI11: *
R12: выбор из выпадающего списка | S12: КДП | T12: выбор из выпадающего списка | U12: 1
A13: 1. Организация воздушного движения (ОрВД) | C13: Раздел | R13: Наблюдение (УИП 2) | S13: Раздел | T13: Раздел | U13: Раздел | V13: Раздел
R14: Наблюдение (УИП 2) | S14: выбор из выпадающего списка | T14: выбор из выпадающего списка | U14: выбор из выпадающего списка
A15: 1.1.Модернизация укрупненных центров ЕС ОрВД (включая строительство/реконструкция) | C15: Подраздел | R15: Хоз деятельность (УИП 6 Прочее) | S15: Подраздел | T15: Подраздел | U15: Подраздел | V15: Подраздел
S16: выбор из выпадающего списка | T16: выбор из выпадающего списка | U16: выбор из выпадающего списка
S17: выбор из выпадающего списка | T17: выбор из выпадающего списка | U17: выбор из выпадающего списка
S18: выбор из выпадающего списка | T18: выбор из выпадающего списка | U18: выбор из выпадающего списка
S19: выбор из выпадающего списка | T19: выбор из выпадающего списка | U19: выбор из выпадающего списка
A21: Примечание:
A22: Колонки (1)-(42) для печатной формы заявки
A23: Колонки (1)-(42),(*) - для электронной формы заявки
A24: В случае проставления признака "да" в колонке "Относится к Стратегии цифровой трансформации (да/нет)" заполнятся приложение к Приложению № 3.3
AC25: ОН - мероприятия общего назначения (АНО), ПД - мероприятия по прочим видам деятельности.

Sheet Приложение к Пр 3.3 заявка
Y1: ПРИЛОЖЕНИЕ К ПРИЛОЖЕНИЮ № 3.3
Y2: К ПОРЯДКУ ТЕКУЩЕГО ПЛАНИРОВАНИЯ ПРОИЗВОДСТВЕННО-ХОЗЯЙСТВЕННОЙ ДЕЯТЕЛЬНОСТИ ФГУП «ГОСКОРПОРАЦИЯ ПО ОрВД»
A3: Приложение к форме заявки на мероприятия в централизованный план 1- 2 группы подгрупп 104.1, 105.1, 201.1*
AI4: тыс. рублей
A5: № п/п | B5: КМ | C5: № инициативы СЦТ | D5: Код мероприятия | E5: Наименование мероприятия | F5: Номер договора и дата/планируемый | G5: Стоимость мероприятия (этапа) планируемая | H5: Лимит финансирования на ____ год, в т.ч. | I5: Текущий год | O5: Платежи последующих периодов
O6: 1-й плановый год | V6: 2-й плановый год | AC6: последующие годы
I7: Ключевые показатели эффективности (КПЭ) цифровой трансформации** | O7: Итого | P7: Ключевые показатели эффективности (КПЭ) цифровой трансформации** | V7: Итого | W7: Ключевые показатели эффективности (КПЭ) цифровой трансформации** | AC7: Итого | AD7: Ключевые показатели эффективности (КПЭ) цифровой трансформации**
I8: КПЭ 17 | J8: КПЭ 23 | K8: КПЭ 19 | L8: КПЭ 26 | M8: КПЭ 20 | N8: КПЭ 22 | P8: КПЭ 17 | Q8: КПЭ 23 | R8: КПЭ 19 | S8: КПЭ 26 | T8: КПЭ 20 | U8: КПЭ 22 | W8: КПЭ 17 | X8: КПЭ 23 | Y8: КПЭ 19 | Z8: КПЭ 26 | AA8: КПЭ 20 | AB8: КПЭ 22 | AD8: КПЭ 17 | AE8: КПЭ 23 | AF8: КПЭ 19 | AG8: КПЭ 26 | AH8: КПЭ 20 | AI8: КПЭ 22
A9: 1 | C9: 2 | D9: 3 | E9: 4 | F9: 5 | G9: 6 | H9: 7 | I9: 8 | J9: 9 | K9: 11 | L9: 12 | M9: 13 | N9: 14 | O9: 15 | P9: 16 | Q9: 17 | R9: 19 | S9: 20 | T9: 21 | U9: 22 | V9: 23 | W9: 24 | X9: 25 | Y9: 27 | Z9: 28 | AA9: 29 | AB9: 30 | AC9: 31 | AD9: 32 | AE9: 33 | AF9: 35 | AG9: 36 | AH9: 37 | AI9: 38
A10: 1 | C10: 1 | E10: Мероприятие 1 | F10: № ___ от _____ | G10: =H10+O10+V10+AC10 -> 500000 | H10: =SUM(I10:N10) -> 100000 | I10: =SUM(I11:I15) -> 30000 | J10: 20000 | K10: =SUM(K11:K15) -> 30000 | L10: =SUM(L11:L15) -> 20000 | M10: =SUM(M11:M15) -> 0 | N10: =SUM(N11:N15) -> 0 | O10: =SUM(P10:U10) -> 100000 | P10: =SUM(P11:P15) -> 30000 | Q10: =SUM(Q11:Q15) -> 20000 | R10: =SUM(R11:R15) -> 30000 | S10: =SUM(S11:S15) -> 20000 | T10: =SUM(T11:T15) -> 0 | U10: =SUM(U11:U15) -> 0 | V10: =SUM(W10:AB10) -> 100000 | W10: =SUM(W11:W15) -> 30000 | X10: =SUM(X11:X15) -> 20000 | Y10: =SUM(Y11:Y15) -> 30000 | Z10: =SUM(Z11:Z15) -> 20000 | AA10: =SUM(AA11:AA15) -> 0 | AB10: =SUM(AB11:AB15) -> 0 | AC10: =SUM(AD10:AI10) -> 200000 | AD10: =SUM(AD11:AD15) -> 0 | AE10: =SUM(AE11:AE15) -> 0 | AF10: =SUM(AF11:AF15) -> 100000 | AG10: =SUM(AG11:AG15) -> 100000 | AH10: =SUM(AH11:AH15) -> 0 | AI10: =SUM(AI11:AI15) -> 0
C11: 1 | E11: Код ОКПД2 | I11: 30000 | P11: 30000 | W11: 30000
C12: 1 | E12: Код ОКПД2 | J12: 20000 | Q12: 20000 | X12: 20000
C13: 1 | E13: Код ОКПД2 | K13: 20000 | R13: 30000 | AF13: 100000
C14: 1 | E14: Код ОКПД2 | K14: 10000 | Y14: 30000
C15: 1 | E15: Код ОКПД2 | L15: 20000 | S15: 20000 | Z15: 20000 | AG15: 100000
A16: 2 | C16: 3 | E16: Мероприятие 2 | F16: Планируемый | G16: =H16+O16+V16+AC16 -> 30000 | H16: =SUM(H17) -> 30000 | I16: =SUM(I17) -> 0 | K16: 0 | M16: 0 | N16: =SUM(N17) -> 30000 | O16: =SUM(P16:U16) -> 0 | P16: =SUM(P17) -> 0 | R16: =SUM(R17) -> 0 | T16: =SUM(T17) -> 0 | U16: =SUM(U17) -> 0 | V16: =W16+Y16+AA16+AB16 -> 0 | W16: =SUM(W17) -> 0 | Y16: =SUM(Y17) -> 0 | AA16: =SUM(AA17) -> 0 | AB16: =SUM(AB17) -> 0 | AC16: =SUM(AD16:AI16) -> 0 | AD16: =SUM(AD17) -> 0 | AF16: =SUM(AF17) -> 0 | AH16: =SUM(AH17) -> 0 | AI16: =SUM(AI17) -> 0
C17: 3 | E17: Код ОКПД2 | G17: =H17+O17+V17+AC17 -> 30000 | H17: =I17+K17+M17+N17 -> 30000 | I17: 0 | K17: 0 | M17: 0 | N17: 30000 | O17: =SUM(P17:U17) -> 0 | P17: 0 | R17: 0 | T17: 0 | U17: 0 | V17: 0 | W17: 0 | Y17: 0 | AA17: 0 | AB17: 0 | AC17: 0 | AD17: 0 | AF17: 0 | AH17: 0 | AI17: 0
A18: 3 | C18: 6 | E18: Мероприятие 3 | F18: Планируемый | G18: =H18+O18+V18+AC18 -> 200000 | H18: =I18+K18+M18+N18 -> 70000 | I18: =SUM(I19) -> 0 | K18: =SUM(K19) -> 0 | M18: =SUM(M19) -> 70000 | N18: =SUM(N19) -> 0 | O18: =P18+R18+T18+U18 -> 100000 | P18: =SUM(P19) -> 100000 | R18: =SUM(R19) -> 0 | T18: =SUM(T19) -> 0 | U18: =SUM(U19) -> 0 | V18: 30000 | W18: =SUM(W19) -> 0 | Y18: =SUM(Y19) -> 0 | AA18: =SUM(AA19) -> 0 | AB18: =SUM(AB19) -> 0 | AC18: =AD18+AF18+AH18+AI18 -> 0 | AD18: =SUM(AD19) -> 0 | AF18: =SUM(AF19) -> 0 | AH18: =SUM(AH19) -> 0 | AI18: =SUM(AI19) -> 0
C19: 6 | E19: Код ОКПД2 | G19: =H19+O19+V19+AC19 -> 170000 | H19: =I19+K19+M19+N19 -> 70000 | I19: 0 | K19: 0 | M19: 70000 | N19: 0 | O19: =P19+R19+T19+U19 -> 100000 | P19: 100000 | R19: 0 | T19: 0 | U19: 0 | V19: =W19+Y19+AA19+AB19 -> 0 | W19: 0 | Y19: 0 | AA19: 0 | AB19: 0 | AC19: =AD19+AF19+AH19+AI19 -> 0 | AD19: 0 | AF19: 0 | AH19: 0 | AI19: 0
A20: N
A22: * Приложение заполняется только в том случае , если мероприятие относится к Стратегии цифровой трансформации (СЦТ)
A23: ** Определяются в соответствии с общероссийским классификатором по видам экономической деятельности (ОКПД2).
A24: В гр.2 указывается № инициативы СЦТ в соответсвии с утвержденной СЦТ ФГУП «Госкорпорация по ОрВД» до 2030 года и действующей редакцией методических рекомендаций по цифровой трансформации государственных корпораций и компаний с государственным участием (приложение №3)
A25: Сумма КПЭ: по гр. 8-14 должна быть равна лимиту финансирования текущего года, отраженному в гр. 7; по гр. 16-22 должна быть равна лимиту 1-го планового года, отраженному в гр. 15; по гр. 24-30 должна быть равна лимиту 2-го планового года, отраженному в гр. 23; по гр. 32-38 должна быть равна лимиту последующих годов, отраженному в гр. 31;
A26: Гр. 6 равна сумме гр. 7, 15,23,31
A27: В гр. 8; гр. 16; гр. 24; гр.32 (КПЭ 17 -"Увеличение вложений в российские решения в сфере информационных технологий")- указывается объем расходов на российское ПО, включенное в Единый реестр российских программ для электронных вычислительных машин и баз данных или в Единый реестр программ для электронных вычислительных машин и баз данных государств - членов Евразийского экономического союза, и связанные с ним работы (услуги). В случае если ПО является свободно распространяемым, но сведения о таком программном обеспечении не включены в Единый реестр российского ПО, то такое ПО относится к иностранному ПО и заполняются гр. 9; гр. 17; гр. 25; гр.33 в соответствующем периоде;
A28: В гр. 9, гр.17, гр. 25, гр. 33 (КПЭ 23 " Увеличение расходов на информационные технологии") - указывается объем расходов на иностранное ПО и связанные с ним работы (услуги).
A29: В гр. 11; гр. 19; гр. 27; гр.35 (КПЭ 19 "Увеличение вложений в радиоэлектронную продукцию российского происхождения, в том числе в телекоммуникационное оборудование и программно-аппаратные комплексы"- указывается объем расходов государственной компании на радиоэлектронную продукцию российского происхождения, в том числе телекоммуникационное оборудование и программно-аппаратные комплексы. Под радиоэлектронной продукцией российского происхождения понимается радиоэлектронная продукция, сведения о которой включены в реестр российской промышленной продукции (согласно постановлению Правительства Российской Федерации от 17.07.2015 N 719). Также включаются расходы на радиоэлектронную продукцию, которая включена в евразийский реестр промышленных товаров государств - членов Евразийского экономического союза. В данные графы не включаются расходы на работы (услуги), связанные с радиоэлектронной продукцией. Указанные затраты отражаются в гр. 12,гр.20,гр.28, гр. 36 в соответствующем периоде.
A30: В гр. 12; гр. 20; гр. 28; гр.36 (КПЭ 26 "Увеличение расходов, направленных на закупку радиоэлектронной продукции, телекоммуникационного оборудования и программно-аппаратных комплексов, а также связанных с ней работ (услуг)") - указывается объем расходов государственной компании на радиоэлектронную продукцию иностранного производства, в том числе телекоммуникационное оборудование и программно-аппаратные комплексы, а также связанные с ней работы (услуги), а также работы (услуги) связанные с приобретением радиоэлектронной продукции российского производства.
A31: В гр. 13; гр. 21; гр. 29; гр.37 (КПЭ 20 "Объем затрат на исследования и разработки, направленных на создание и развитие передовых и критически важных для отрасли цифровых технологий и решений, в том числе новых производственных технологий, связанных с интенсивным применением информационно-коммуникационных технологий в рамках реализации инициатив (проектов) СЦТ") - указывается объем затрат на научные исследования и разработки (НИОКР), направленных на создание и развитие передовых и критически важных для отрасли цифровых технологий и решений, в том числе новых производственных технологий, связанных с интенсивным применением информационно-коммуникационных технологий.
A32: В гр. 13; гр. 21; гр. 29; гр.37 (КПЭ 22 "Объем расходов государственных компаний на реализацию инициатив (мероприятий), связанных с созданием, внедрением и применением технологий и решений в сфере искусственного интеллекта") - указываются расходы связанные с технологиями и решениями в сфере искусственного интеллекта.

Sheet Показатели ИПР ПДП
B2: Справочник показателей инвестиционной программы Предприятия и программы деятельности Предприятия
B4: Показатели ИПР | D4: Показатели ПДП
B5: Завершение создания УЦ | D5: Число введенных в эксплуатацию укрупненных центров управления воздушным движением | E5: УЦ УВД
B6: Модернизация УЦ | D6: Число введённых в эксплуатацию доплеровских азимутально-дальномерных радиомаяков, радиотехнических систем ближней навигации, дальномерных радиомаяков | E6: DME
B7: Создание резервных центров | D7: Число введенных в эксплуатацию приводных радиостанций | E7: ПРС
B8: Модернизация КТС АУВД | D8: Число введенных в эксплуатацию средств АУВД аэродромов | E8: АУВД
B9: АРП | D9: Число введенных в эксплуатацию радиомаячных систем посадки | E9: РМС
B10: ОРЛ-А | D10: Число введенных в эксплуатацию аэродромных радиолокационных комплексов (модернизация) | E10: АРЛК
B11: ОРЛ-Т | D11: Число введенных в эксплуатацию трассовых радиолокационных комплексов (модернизация) | E11: ТРЛК
B12: МВРЛ | D12: Число введенных в эксплуатацию средств функционального дополнения GBAS (локальная контрольно-корректирующая станция ЛККС-А-2000) | E12: ЛККС
B13: РЛС ОЛП | D13: Число введенных в эксплуатацию средств вторичной моноимпульсной радиолокации (МВРЛ) | E13: МВРЛ
